starting to run
/usr/local/oge_spool/ielsc-31/job_scripts/8081287: line 4: export: `=': not a valid identifier
/usr/local/oge_spool/ielsc-31/job_scripts/8081287: line 4: export: `ems/elsc-labs/sompolinsky-h/nischal.mainali/anaconda3/bin:PATH': not a valid identifier
/usr/local/oge_spool/ielsc-31/job_scripts/8081287: line 5: export: `=': not a valid identifier
/usr/local/oge_spool/ielsc-31/job_scripts/8081287: line 5: export: `ems/elsc-labs/sompolinsky-h/nischal.mainali/anaconda3/bin:PATH': not a valid identifier
/usr/local/oge_spool/ielsc-31/job_scripts/8081287: line 7: ped: command not found
/usr/local/oge_spool/ielsc-31/job_scripts/8081287: line 7: PWD: command not found
/tmp/8081287.1.elsc.q:/ems/elsc-labs/sompolinsky-h/nischal.mainali/anaconda3/envs/conda-env/bin:/ems/elsc-labs/sompolinsky-h/nischal.mainali/anaconda3/condabin:/ems/elsc-labs/R-3.6.1/bin:/opt/oge/bin/lx24-amd64:/usr/lib/llvm/8/bin:/usr/lib/llvm/6/bin:/usr/local/sbin:/usr/local/bin:/usr/sbin:/usr/bin:/sbin:/bin:/opt/bin:/usr/local/bin/ANTS:/ems/elsc-labs/fsl511/bin:/home/mrtrix3/bin:/opt/slurm/bin
Files already downloaded and verified
Files already downloaded and verified
#######################################
Evaluation with a full NN
Accuracy of the network on the 10000 test images: 0.9407 #VGG16 BEST
#######################################
creating feature extractor
Traceback (most recent call last):
  File "nn+gp01.py", line 80, in <module>
    x_train = net(x_train_0).detach().numpy()
  File "/ems/elsc-labs/sompolinsky-h/nischal.mainali/anaconda3/envs/conda-env/lib/python3.6/site-packages/torch/nn/modules/module.py", line 541, in __call__
    result = self.forward(*input, **kwargs)
  File "/ems/elsc-labs/sompolinsky-h/nischal.mainali/Desktop/DL as GP/neural-tangents/examples/cifar10_models/vgg.py", line 29, in forward
    x = self.features(x)
  File "/ems/elsc-labs/sompolinsky-h/nischal.mainali/anaconda3/envs/conda-env/lib/python3.6/site-packages/torch/nn/modules/module.py", line 541, in __call__
    result = self.forward(*input, **kwargs)
  File "/ems/elsc-labs/sompolinsky-h/nischal.mainali/anaconda3/envs/conda-env/lib/python3.6/site-packages/torch/nn/modules/container.py", line 92, in forward
    input = module(input)
  File "/ems/elsc-labs/sompolinsky-h/nischal.mainali/anaconda3/envs/conda-env/lib/python3.6/site-packages/torch/nn/modules/module.py", line 541, in __call__
    result = self.forward(*input, **kwargs)
  File "/ems/elsc-labs/sompolinsky-h/nischal.mainali/anaconda3/envs/conda-env/lib/python3.6/site-packages/torch/nn/modules/conv.py", line 345, in forward
    return self.conv2d_forward(input, self.weight)
  File "/ems/elsc-labs/sompolinsky-h/nischal.mainali/anaconda3/envs/conda-env/lib/python3.6/site-packages/torch/nn/modules/conv.py", line 342, in conv2d_forward
    self.padding, self.dilation, self.groups)
RuntimeError: [enforce fail at CPUAllocator.cpp:64] . DefaultCPUAllocator: can't allocate memory: you tried to allocate 327680000 bytes. Error code 12 (Cannot allocate memory)

